Workbook
Name adjusted_beta: '15_WACC'!$F$11
Name Capex_pct: '00_Assumptions'!$C$42
Name effective_tax_rate: '15_WACC'!$F$17
Name equity_risk_premium: '15_WACC'!$F$12
Name risk_free_rate: '15_WACC'!$F$10
Name Tax_Rate: '00_Assumptions'!$B$11
Name Terminal_Growth: '00_Assumptions'!$B$19
Name wacc_output: '15_WACC'!$F$19

Sheet 00_Assumptions
A1: NVIDIA Corporation — Model Assumptions
A2: Valuation Date: October 17, 2025 | Currency: USD millions | Model: L3 DCF (FCFF / Gordon Growth) | Forecast: FY2026–FY2030
A4: 1. WACC & COST OF CAPITAL
A5: Input | B5: Value | C5: FY2026F | D5: FY2027F | E5: FY2028F | F5: FY2029F | G5: FY2030F | H5: Rationale | I5: Source / Sheet
A6: Risk-free rate | B6: ='15_WACC'!F10 -> 0.0407 | H6: US 10-Year Treasury yield as of October 17, 2025. Represents the minimum risk-free return investors require. | I6: 15_WACC!F10 | US Treasury / FRED
A7: Equity risk premium (ERP) | B7: ='15_WACC'!F12 -> 0.05 | H7: Damodaran implied ERP for US market. Represents the additional return equity investors demand over the risk-free rate. | I7: 15_WACC!F12 | Damodaran (Jan 2025)
A8: Adjusted beta (Blume) | B8: ='15_WACC'!F11 -> 1.7728261 | H8: Blume-adjusted beta from regression of NVDA vs S&P 500 (60M weekly). Formula: β_adj = 0.67×β_raw + 0.33×1.0. Pulls from 14_Beta sheet. | I8: 15_WACC!F11 | Yahoo Finance / 14_Beta
A9: Cost of equity (CAPM) | B9: ='15_WACC'!F9 -> 0.12934131 | H9: CAPM: Ke = Rf + β × ERP. Represents the return required by equity investors based on systematic risk. | I9: 15_WACC!F9 (computed)
A10: Pre-tax cost of debt | B10: ='15_WACC'!F16 -> 0.028285274 | H10: Weighted average interest rate on NVIDIA's outstanding debt. Derived from interest expense / average debt balance. | I10: 15_WACC!F16 | 13_DebtSchedule
A11: Effective tax rate (FY2025) | B11: ='15_WACC'!F17 -> 0.13264942 | H11: FY2025 actual effective tax rate (Income Tax / Pre-Tax Income). Used as proxy for normalized rate in WACC. Forecast rates in Section 4. | I11: 15_WACC!F17 | 04a_Projection_IS!F71
A12: Weight of equity | B12: ='15_WACC'!F8 -> 0.99810266 | H12: Market cap / (Market cap + Total debt). NVIDIA is near debt-free — equity weight is 99.8%. | I12: 15_WACC!F8 (computed)
A13: Weight of debt | B13: ='15_WACC'!F15 -> 0.0018973367 | H13: Total debt / (Market cap + Total debt). Minimal debt — 0.19% weight. | I13: 15_WACC!F15 (computed)
A14: WACC ✦ | B14: ='15_WACC'!F19 -> 0.12914245 | H14: Weighted Average Cost of Capital: w_e × Ke + w_d × Kd × (1–t). Primary discount rate for FCF discounting. | I14: 15_WACC!F19 (computed) | named range: wacc_output
A16: 2. DCF ASSUMPTIONS
A17: Input | B17: Value | C17: FY2026F | D17: FY2027F | E17: FY2028F | F17: FY2029F | G17: FY2030F | H17: Rationale | I17: Source / Sheet
A18: Projection horizon | B18: 5 | H18: Standard 5-year explicit forecast period. NVIDIA's Data Center hyper-growth makes longer periods too speculative. | I18: Convention
A19: Terminal growth rate (g) ✦ | B19: ='05b_DCF'!C13 -> 0.04 | H19: Long-run nominal GDP growth (3%–5% range). Set at 4% — midpoint, consistent with NVIDIA's presence in structural AI growth market. | I19: 05b_DCF!C13 | named range: terminal_growth
A20: Terminal value method | B20: Gordon Growth | H20: Gordon Growth Model: TV = FCF₅ × (1+g) / (WACC–g). Single terminal value method used. Exit multiple (EV/EBITDA) recommended as cross-check — see 05b_DCF. | I20: 05b_DCF rows 24–28
A21: Diluted shares outstanding | B21: ='05b_DCF'!C20 -> 24300 | H21: Diluted share count as of Q2 FY2025 (in millions). Used to convert equity value to per-share price. | I21: 05b_DCF!C20 | NVIDIA 10-K
A22: Valuation date | B22: October 17, 2025 | H22: Date of valuation. Market price on this date: $183.22. Implied price: $109.26 (–39.9%). | I22: Manual input
A23: Market price (Oct 17, 2025) | B23: 183.22 | H23: NVIDIA closing price on the valuation date. Used as reference point for premium/discount calculation. | I23: 16_MarketData | Yahoo Finance
A25: 3. REVENUE GROWTH ASSUMPTIONS — Base Case ($ millions)
A26: Input | B26: Value | C26: FY2026F | D26: FY2027F | E26: FY2028F | F26: FY2029F | G26: FY2030F | H26: Rationale | I26: Source / Sheet
A27: Data Center revenue — YoY growth | B27: Primary driver | C27: 0.69 | D27: 0.42 | E27: 0.27 | F27: 0.16 | G27: 0.22 | H27: AI accelerator demand (H100/H200/B200). Dominant segment at 88% of FY2025 revenue. Base case reflects decelerating but still exceptional growth. | I27: 04a_Projection_IS rows 5–9
A28: Gaming revenue — YoY growth | B28: Stable/slow | C28: 0.05 | D28: 0.03 | E28: 0.02 | F28: 0.02 | G28: 0.03 | H28: PC GPU upgrade cycle. Mature segment. Base case assumes modest growth recovering post-crypto hangover. | I28: 04a_Projection_IS rows 11–15
A29: Professional Visualization — YoY growth | B29: Steady | C29: 0.06 | D29: 0.07 | E29: 0.05 | F29: 0.04 | G29: 0.05 | H29: Workstation GPU (Quadro/RTX). Stable enterprise market. Base case: low-to-mid single digit growth. | I29: 04a_Projection_IS rows 17–21
A30: Automotive — YoY growth | B30: High growth | C30: 0.45 | D30: 0.5 | E30: 0.35 | F30: 0.26 | G30: 0.35 | H30: DRIVE Orin/Thor autonomous vehicle platform. Long adoption cycle but accelerating. Base case is conservative vs upside (65%+). | I30: 04a_Projection_IS rows 23–27
A31: OEM & Other — YoY growth | B31: Minimal | C31: 0.02 | D31: 0.03 | E31: 0.02 | F31: 0.02 | G31: 0.03 | H31: Legacy OEM business declining/flat. Smallest segment. Immaterial to total revenue. | I31: 04a_Projection_IS rows 29–33
A32: Total revenue — YoY growth ✦ | B32: See forecast | C32: 0.62 | D32: 0.39 | E32: 0.26 | F32: 0.16 | G32: 0.21 | H32: Blended growth driven primarily by Data Center. FY2026 +62% reflects continued AI buildout; decelerates through FY2030. | I32: 04a_Projection_IS row 36 (computed)
A34: 4. MARGIN & COST ASSUMPTIONS
A35: Input | B35: Value | C35: FY2026F | D35: FY2027F | E35: FY2028F | F35: FY2029F | G35: FY2030F | H35: Rationale | I35: Source / Sheet
A36: Effective tax rate — Base case | B36: 15.0% (FY26) | C36: 0.15 | D36: 0.145 | E36: 0.145 | F36: 0.14 | G36: 0.14 | H36: Forecast ETR stepping up from FY2025 actual 13.3% towards normalized 14–15% range. Reflects global minimum tax (Pillar Two) impact. | I36: 04a_Projection_IS rows 62–65
A37: Cash & equivalents as % of revenue | B37: 28% (FY26) | C37: 0.28 | D37: 0.25 | E37: 0.23 | F37: 0.22 | G37: 0.21 | H37: NVIDIA holds significant net cash. Declining % of revenue as absolute revenue scales rapidly. Used to compute interest income. | I37: 04a_Projection_IS row 55
A38: Assumed yield on cash | B38: 3.45% (FY26) | C38: 0.0345 | D38: 0.0325 | E38: 0.0325 | F38: 0.031 | G38: 0.031 | H38: Interest earned on cash/short-term investments. Reflects prevailing money market / short-duration bond rates. Declining with rate cycle. | I38: 04a_Projection_IS row 57
A39: Other income (net) — Base case ($M) | B39: Flat $1,000M from FY27 (conservative; excl. equity gains) | C39: 1700 | D39: 1000 | E39: 1000 | F39: 1000 | G39: 1000
A40: 5. CAPITAL EXPENDITURE & DEPRECIATION
A41: Input | B41: Value | C41: FY2026F | D41: FY2027F | E41: FY2028F | F41: FY2029F | G41: FY2030F | H41: Rationale | I41: Source / Sheet
A42: CapEx as % of revenue ✦ | B42: 3.0% (FY26) | C42: 0.03 | D42: 0.032 | E42: 0.033 | F42: 0.03 | G42: 0.028 | H42: NVIDIA is asset-light (fabless). CapEx covers data centers, tools, and leasehold improvements. % slightly increasing as hyperscaler infrastructure spend rises. | I42: 12_FixedAssets row 7
A43: Average useful life (years) | B43: ='11_DA'!B3 -> 5 | H43: Weighted average depreciation period for fixed assets and capitalized costs. Used to compute annual D&A schedule in 11_DA sheet. | I43: 11_DA!B3
A44: D&A — FY2026F ($M) | B44: 3046 | C44: 3046 | D44: 4817 | E44: 6921 | F44: 9078 | G44: 11117 | H44: Projected D&A driven by CapEx schedule and 5-year useful life assumption. Adds back to EBIT to derive EBITDA and FCFF. | I44: 11_DA row 19 (computed)
...

Sheet 01_Historical_IS
A1: Income Statement
B2: 2020 | C2: 2021 | D2: 2022 | E2: 2023 | F2: 2024 | G2: 2025 | J2: Common-Size Income Statements
A3: Revenue | B3: 10918 | C3: 16675 | D3: 26914 | E3: 26974 | F3: 60922 | G3: 130497 | K3: 2020 | L3: 2021 | M3: 2022 | N3: 2023 | O3: 2024 | P3: 2025
A4: Cost of revenue( COGS) | B4: 4150 | C4: 6279 | D4: 9439 | E4: 11618 | F4: 16621 | G4: 32639 | J4: Revenue | K4: 1 | L4: 1 | M4: 1 | N4: =E3/E3 -> 1 | O4: =F3/F3 -> 1 | P4: =G3/G3 -> 1
A5: Gross profit | B5: =B3-B4 -> 6768 | C5: =C3-C4 -> 10396 | D5: =D3-D4 -> 17475 | E5: 15356 | F5: 44301 | G5: 97858 | J5: Cost of revenue | K5: =B4/B3 -> 0.38010625 | L5: =C4/C3 -> 0.37655172 | M5: =D4/D3 -> 0.35070967 | N5: =E4/E3 -> 0.43071106 | O5: =F4/F3 -> 0.27282427 | P5: =G4/G3 -> 0.25011303
B6: 0 | C6: =(C5/B5)-1 -> 0.53605201 | D6: =(D5/C5)-1 -> 0.68093497 | E6: =(E5/D5)-1 -> -0.12125894 | F6: =(F5/E5)-1 -> 1.884931 | G6: =(G5/F5)-1 -> 1.2089343
A7: Operating expenses | J7: Gross profit | K7: =B5/B3 -> 0.61989375 | L7: =C5/C3 -> 0.62344828 | M7: =D5/D3 -> 0.64929033 | N7: =E5/E3 -> 0.56928894 | O7: =F5/F3 -> 0.72717573 | P7: =G5/G3 -> 0.74988697
A8: Research and development | B8: ='10_GrowthRates'!I6 -> 2829 | C8: ='10_GrowthRates'!J6 -> 3924 | D8: ='10_GrowthRates'!K6 -> 5268 | E8: 7339 | F8: 8675 | G8: 12914 | J8: Operating expenses
A9: Sales, general and administrative | B9: 1093 | C9: 1940 | D9: 2166 | E9: 2440 | F9: 2654 | G9: 3491 | J9: Research and development | K9: =B8/B3 -> 0.25911339 | L9: =C8/C3 -> 0.23532234 | M9: =D8/D3 -> 0.19573456 | N9: =E8/E3 -> 0.27207681 | O9: =F8/F3 -> 0.14239519 | P9: =G8/G3 -> 0.098960129
A10: Acquisition termination cost | B10: 0 | C10: 0 | D10: 0 | E10: 1353 | F10: 0 | G10: 0 | J10: Sales, general and administrative | K10: =B9/B3 -> 0.10010991 | L10: =C9/C3 -> 0.11634183 | M10: =D9/D3 -> 0.080478561 | N10: =E9/E3 -> 0.090457478 | O10: =F9/F3 -> 0.043563901 | P10: =G9/G3 -> 0.026751573
A11: Total operating expenses | B11: 3922 | C11: 5864 | D11: 7434 | E11: 11132 | F11: 11329 | G11: 16405 | J11: Acquisition termination cost | K11: =IFERROR((B10/B3), " _ ") -> 0 | L11: =IFERROR((C10/C3), " _ ") -> 0 | M11: =IFERROR((D10/D3), " _ ") -> 0 | N11: =IFERROR(E10/E3,"_") -> 0.050159413 | O11: =IFERROR(F10/F3,"_") -> 0 | P11: =IFERROR(G10/G3,"_") -> 0
A12: EBIT (Operating income ) | B12: =B5-B11 -> 2846 | C12: =C5-C11 -> 4532 | D12: =D5-D11 -> 10041 | E12: 4224 | F12: 32972 | G12: 81453 | J12: Total operating expenses | K12: =B11/B3 -> 0.3592233 | L12: =C11/C3 -> 0.35166417 | M12: =D11/D3 -> 0.27621312 | N12: =E11/E3 -> 0.41269371 | O12: =F11/F3 -> 0.1859591 | P12: =G11/G3 -> 0.1257117
A13: D&A | B13: 381 | C13: 1098 | D13: 1174 | E13: ='03_Historical_CF'!B7 -> 1544 | F13: ='03_Historical_CF'!C7 -> 1508 | G13: ='03_Historical_CF'!D7 -> 1864 | J13: EBIT (Operating income) | K13: =B12/B3 -> 0.26067045 | L13: =C12/C3 -> 0.27178411 | M13: =D12/D3 -> 0.37307721 | N13: =E12/E3 -> 0.15659524 | O13: =F12/F3 -> 0.54121664 | P13: =G12/G3 -> 0.62417527
A14: EBITDA | B14: =B12+B13 -> 3227 | C14: =C12+C13 -> 5630 | D14: =D12+D13 -> 11215 | E14: =E12+E13 -> 5768 | F14: =F12+F13 -> 34480 | G14: =G12+G13 -> 83317 | J14: =A13 -> D&A | K14: =B13/B3 -> 0.034896501 | L14: =C13/C3 -> 0.065847076 | M14: =D13/D3 -> 0.043620421 | N14: =E13/E3 -> 0.057240305 | O14: =F13/F3 -> 0.024752963 | P14: =G13/G3 -> 0.014283853
A15: Interest income | B15: 178 | C15: 57 | D15: 29 | E15: 267 | F15: 866 | G15: 1786 | J15: =A14 -> EBITDA | K15: =B14/B3 -> 0.29556695 | L15: =C14/C3 -> 0.33763118 | M15: =D14/D3 -> 0.41669763 | N15: =E14/E3 -> 0.21383555 | O15: =F14/F3 -> 0.5659696 | P15: =G14/G3 -> 0.63845912
A16: Interest expense | B16: -52 | C16: -184 | D16: -236 | E16: -262 | F16: -257 | G16: -247 | J16: Interest income | K16: =B15/B3 -> 0.016303352 | L16: =C15/C3 -> 0.0034182909 | M16: =D15/D3 -> 0.0010775061 | N16: =E15/E3 -> 0.0098984207 | O16: =F15/F3 -> 0.014214898 | P16: =G15/G3 -> 0.013686138
A17: Other, net | B17: -2 | C17: 4 | D17: 107 | E17: -48 | F17: 237 | G17: 1034 | J17: Interest expense | K17: =B16/B3 -> -0.0047627771 | L17: =C16/C3 -> -0.011034483 | M17: =D16/D3 -> -0.0087686706 | N17: =E16/E3 -> -0.009713057 | O17: =F16/F3 -> -0.0042185089 | P17: =G16/G3 -> -0.0018927638
A18: Other income (expense), net | B18: =SUM(B15:B17) -> 124 | C18: =SUM(C15:C17) -> -123 | D18: =SUM(D15:D17) -> -100 | E18: -43 | F18: 846 | G18: 2573 | J18: Other, net | K18: =B17/B3 -> -0.00018318373 | L18: =C17/C3 -> 0.00023988006 | M18: =D17/D3 -> 0.0039756261 | N18: =E17/E3 -> -0.0017794914 | O18: =F17/F3 -> 0.0038902203 | P18: =G17/G3 -> 0.0079235538
A19: EBT (Income before income tax) | B19: 2970 | C19: 4409 | D19: 9941 | E19: 4181 | F19: 33818 | G19: 84026 | J19: Other income (expense), net | K19: =B18/B3 -> 0.011357391 | L19: =C18/C3 -> -0.0073763118 | M19: =D18/D3 -> -0.0037155384 | N19: =E18/E3 -> -0.0015941277 | O19: =F18/F3 -> 0.013886609 | P19: =G18/G3 -> 0.019716928
A20: Income tax expense (benefit) | B20: 174 | C20: 77 | D20: 189 | E20: -187 | F20: 4058 | G20: 11146 | J20: EBT (Income before income tax ) | K20: =B19/B3 -> 0.27202784 | L20: =C19/C3 -> 0.2644078 | M20: =D19/D3 -> 0.36936167 | N20: =E19/E3 -> 0.15500111 | O20: =F19/F3 -> 0.55510325 | P20: =G19/G3 -> 0.6438922
A21: Net income | B21: 2796 | C21: 4332 | D21: 9752 | E21: 4368 | F21: 29760 | G21: 72880 | J21: Income tax expense (benefit) | K21: =B20/B3 -> 0.015936985 | L21: =C20/C3 -> 0.0046176912 | M21: =D20/D3 -> 0.0070223675 | N21: =E20/E3 -> -0.0069326018 | O21: =F20/F3 -> 0.066609763 | P21: =G20/G3 -> 0.085411925
J22: Net income | K22: =B21/B3 -> 0.25609086 | L22: =C21/C3 -> 0.2597901 | M22: =D21/D3 -> 0.3623393 | N22: =E21/E3 -> 0.16193371 | O22: =F21/F3 -> 0.48849348 | P22: =G21/G3 -> 0.55848027
B25: 2025 | C25: 2024 | D25: 2023
A26: Data Center | B26: 115186 | C26: 47525 | D26: 15005
A27: Compute | B27: 102196 | C27: 38950 | D27: 11317
A28: Networking | B28: 12990 | C28: 8575 | D28: 3688
A29: Gaming | B29: 11350 | C29: 10447 | D29: 9067
A30: Professional Visualization | B30: 1878 | C30: 1553 | D30: 1544
A31: Automotive | B31: 1694 | C31: 1091 | D31: 903
A32: OEM and Other | B32: 389 | C32: 306 | D32: 455
A33: Total revenue | B33: 130497 | C33: 60922 | D33: 26974
B36: 2025 | C36: 2024 | D36: 2023
A37: United States | B37: 61257 | C37: 26966 | D37: 8292
A38: Singapore | B38: 23684 | C38: 6831 | D38: 2288
A39: Taiwan | B39: 20573 | C39: 13405 | D39: 6986
A40: China (including Hong Kong) | B40: 17108 | C40: 10306 | D40: 5785
A41: Other | B41: 7875 | C41: 3414 | D41: 3623
A42: Total revenue | B42: 130497 | C42: 60922 | D42: 26974
E50: Growth rate | G50: 2025 | H50: 2024 | I50: 2023
E51: United States | G51: =B37/$B$42 -> 0.46941309 | H51: =C37/$C$42 -> 0.44263156 | I51: =D37/$D$42 -> 0.30740713
...

Sheet 02_Historical_BS
A1: Balance Sheet | J1: Common-size Balance Sheet
A2: Fiscal Year | B2: 2021 | C2: 2022 | D2: 2023 | E2: 2024 | F2: 2025 | J2: Fiscal Year | K2: 2025 | L2: 2024 | M2: 2023 | N2: 2022 | O2: 2021
A3: Period Ending | B3: Jan '21 Jan 31, 2021 | C3: Jan '22 Jan 30, 2022 | D3: Jan '23 Jan 29, 2023 | E3: Jan '24 Jan 28, 2024 | F3: Jan '25 Jan 26, 2025 | J3: Period Ending | K3: Jan '25 Jan 26, 2025 | L3: Jan '24 Jan 28, 2024 | M3: Jan '23 Jan 29, 2023 | N3: Jan '22 Jan 30, 2022 | O3: Jan '21 Jan 31, 2021
A4: Cash & Equivalents | B4: 847 | C4: 1990 | D4: 3389 | E4: 7280 | F4: 8589 | J4: Cash & Equivalents | K4: =F4/F$17 -> 0.076961676 | L4: =E4/E$17 -> 0.11075949 | M4: =D4/D$17 -> 0.082293235 | N4: =C4/C$17 -> 0.04503587 | O4: =B4/B$17 -> 0.029418916
A5: Short-Term Investments | B5: 10714 | C5: 19218 | D5: 9907 | E5: 18704 | F5: 34621 | J5: Short-Term Investments | K5: =F5/F$17 -> 0.31022123 | L5: =E5/E$17 -> 0.2845667 | M5: =D5/D$17 -> 0.24056627 | N5: =C5/C$17 -> 0.4349243 | O5: =B5/B$17 -> 0.37213018
A6: Cash & Short-Term Investments | B6: 11561 | C6: 21208 | D6: 13296 | E6: 25984 | F6: 43210 | J6: Cash & Short-Term Investments | K6: =F6/F$17 -> 0.38718291 | L6: =E6/E$17 -> 0.39532619 | M6: =D6/D$17 -> 0.3228595 | N6: =C6/C$17 -> 0.47996017 | O6: =B6/B$17 -> 0.4015491
A7: Receivables | B7: 2429 | C7: 4650 | D7: 3827 | E7: 9999 | F7: 23065 | J7: Receivables | K7: =F7/F$17 -> 0.20667378 | L7: =E7/E$17 -> 0.15212695 | M7: =D7/D$17 -> 0.09292895 | N7: =C7/C$17 -> 0.10523457 | O7: =B7/B$17 -> 0.084366642
A8: Inventory | B8: 1826 | C8: 2605 | D8: 5159 | E8: 5282 | F8: 10080 | J8: Inventory | K8: =F8/F$17 -> 0.090321771 | L8: =E8/E$17 -> 0.08036149 | M8: =D8/D$17 -> 0.12527318 | N8: =C8/C$17 -> 0.058953991 | O8: =B8/B$17 -> 0.063422597
A9: Prepaid Expenses | B9: 239 | C9: 366 | D9: 791 | E9: 3080 | F9: 3771 | J9: Prepaid Expenses | K9: =F9/F$17 -> 0.03379002 | L9: =E9/E$17 -> 0.046859786 | M9: =D9/D$17 -> 0.019207421 | N9: =C9/C$17 -> 0.0082829792 | O9: =B9/B$17 -> 0.0083012052
A10: Total Current Assets | B10: 16055 | C10: 28829 | D10: 23073 | E10: 44345 | F10: 80126 | J10: Total Current Assets | K10: =F10/F$17 -> 0.71796848 | L10: =E10/E$17 -> 0.67467442 | M10: =D10/D$17 -> 0.56026905 | N10: =C10/C$17 -> 0.65243171 | O10: =B10/B$17 -> 0.55763954
A11: Property, Plant & Equipment | B11: 2149 | C11: 2778 | D11: 3807 | E11: 3914 | F11: 6283 | J11: Property, Plant & Equipment | K11: =F11/F$17 -> 0.056298779 | L11: =E11/E$17 -> 0.059548442 | M11: =D11/D$17 -> 0.0924433 | N11: =C11/C$17 -> 0.06286917 | O11: =B11/B$17 -> 0.074641381
A12: Operating lease assets | B12: 707 | C12: 829 | D12: 1038 | E12: 1346 | F12: 1793 | J12: Long-Term Investments | K12: =F12/F$17 -> 0.016066164 | L12: =E12/E$17 -> 0.020478335 | M12: =D12/D$17 -> 0.025205187 | N12: =C12/C$17 -> 0.018761174 | O12: =B12/B$17 -> 0.024556285
A13: Goodwill | B13: 4193 | C13: 4349 | D13: 4372 | E13: 4430 | F13: 5188 | J13: Goodwill | K13: =F13/F$17 -> 0.046487039 | L13: =E13/E$17 -> 0.067398978 | M13: =D13/D$17 -> 0.10616289 | N13: =C13/C$17 -> 0.098422613 | O13: =B13/B$17 -> 0.14563579
A14: Intangible Assets, net | B14: 2737 | C14: 2339 | D14: 1676 | E14: 1112 | F14: 807 | J14: Other Intangible Assets | K14: =F14/F$17 -> 0.007231118 | L14: =E14/E$17 -> 0.016918208 | M14: =D14/D$17 -> 0.040697392 | N14: =C14/C$17 -> 0.052934121 | O14: =B14/B$17 -> 0.09506443
A15: Long-Term Deferred Tax Assets | B15: 806 | C15: 1222 | D15: 3396 | E15: 6081 | F15: 10979 | J15: Long-Term Deferred Tax Assets | K15: =F15/F$17 -> 0.098377255 | L15: =E15/E$17 -> 0.092517648 | M15: =D15/D$17 -> 0.082463212 | N15: =C15/C$17 -> 0.027655193 | O15: =B15/B$17 -> 0.02799486
... A17: Total Assets | B17: 28791 | C17: 44187 | D17: 41182 | E17: 65728 | F17: 111601 | J17: Total Assets | K17: =F17/F$17 -> 1 | L17: =E17/E$17 -> 1 | M17: =D17/D$17 -> 1 | N17: =C17/C$17 -> 1 | O17: =B17/B$17 -> 1
A18: Accounts Payable | B18: 1149 | C18: 1783 | D18: 1193 | E18: 2699 | F18: 6310 | J18: Accounts Payable | K18: =IFERROR(F18/F$31,"-") -> 0.19551342 | L18: =IFERROR(E18/E$31,"-") -> 0.11863736 | M18: =IFERROR(D18/D$31,"-") -> 0.062522929 | N18: =IFERROR(C18/C$31,"-") -> 0.10145092 | O18: =IFERROR(B18/B$31,"-") -> 0.096570852
A19: Accrued Expenses | B19: 297 | C19: 409 | D19: 530 | E19: 675 | F19: 848 | J19: Accrued Expenses | K19: =IFERROR(F19/F$31,"-") -> 0.02627502 | L19: =IFERROR(E19/E$31,"-") -> 0.02967033 | M19: =IFERROR(D19/D$31,"-") -> 0.027776322 | N19: =IFERROR(C19/C$31,"-") -> 0.023271693 | O19: =IFERROR(B19/B$31,"-") -> 0.024962179
A20: Short-Term Debt | B20: 999 | C20: 0 | D20: 1250 | E20: 1250 | F20: 0 | J20: Current Portion of Long-Term Debt | K20: =IFERROR(F20/F$31,"-") -> 0 | L20: =IFERROR(E20/E$31,"-") -> 0.054945055 | M20: =IFERROR(D20/D$31,"-") -> 0.065510193 | N20: =IFERROR(C20/C$31,"-") -> 0 | O20: =IFERROR(B20/B$31,"-") -> 0.083963691
A21: Current Portion of Leases | B21: 0 | C21: 144 | D21: 176 | E21: 228 | F21: 288 | J21: Current Portion of Leases | K21: =IFERROR(F21/F$31,"-") -> 0.0089235917 | L21: =IFERROR(E21/E$31,"-") -> 0.010021978 | M21: =IFERROR(D21/D$31,"-") -> 0.0092238352 | N21: =IFERROR(C21/C$31,"-") -> 0.0081934566 | O21: =IFERROR(B21/B$31,"-") -> 0
A22: Current Income Taxes Payable | B22: 0 | C22: 132 | D22: 467 | E22: 296 | F22: 881 | J22: Current Income Taxes Payable | K22: =IFERROR(F22/F$31,"-") -> 0.027297515 | L22: =IFERROR(E22/E$31,"-") -> 0.013010989 | M22: =IFERROR(D22/D$31,"-") -> 0.024474608 | N22: =IFERROR(C22/C$31,"-") -> 0.0075106686 | O22: =IFERROR(B22/B$31,"-") -> 0
A23: Current Unearned Revenue | B23: 288 | C23: 300 | D23: 354 | E23: 764 | F23: 837 | J23: Current Unearned Revenue | K23: =IFERROR(F23/F$31,"-") -> 0.025934189 | L23: =IFERROR(E23/E$31,"-") -> 0.033582418 | M23: =IFERROR(D23/D$31,"-") -> 0.018552487 | N23: =IFERROR(C23/C$31,"-") -> 0.017069701 | O23: =IFERROR(B23/B$31,"-") -> 0.024205749
A24: Other Current Liabilities | B24: 1192 | C24: 1567 | D24: 2593 | E24: 4719 | F24: 8883 | J24: Other Current Liabilities | K24: =IFERROR(F24/F$31,"-") -> 0.27523703 | L24: =IFERROR(E24/E$31,"-") -> 0.20742857 | M24: =IFERROR(D24/D$31,"-") -> 0.13589435 | N24: =IFERROR(C24/C$31,"-") -> 0.08916074 | O24: =IFERROR(B24/B$31,"-") -> 0.10018491
A25: Total Current Liabilities | B25: 3925 | C25: 4335 | D25: 6563 | E25: 10631 | F25: 18047 | J25: Total Current Liabilities | K25: =IFERROR(F25/F$31,"-") -> 0.55918076 | L25: =IFERROR(E25/E$31,"-") -> 0.4672967 | M25: =IFERROR(D25/D$31,"-") -> 0.34395472 | N25: =IFERROR(C25/C$31,"-") -> 0.24665718 | O25: =IFERROR(B25/B$31,"-") -> 0.32988738
A26: Long-Term Debt | B26: 5964 | C26: 10946 | D26: 9703 | E26: 8459 | F26: 8463 | J26: Long-Term Debt | K26: =IFERROR(F26/F$31,"-") -> 0.26222346 | L26: =IFERROR(E26/E$31,"-") -> 0.37182418 | M26: =IFERROR(D26/D$31,"-") -> 0.50851633 | N26: =IFERROR(C26/C$31,"-") -> 0.6228165 | O26: =IFERROR(B26/B$31,"-") -> 0.50126072
A27: Long-Term Leases | B27: 634 | C27: 741 | D27: 902 | E27: 1119 | F27: 1519 | J27: Long-Term Leases | K27: =IFERROR(F27/F$31,"-") -> 0.04706575 | L27: =IFERROR(E27/E$31,"-") -> 0.049186813 | M27: =IFERROR(D27/D$31,"-") -> 0.047272156 | N27: =IFERROR(C27/C$31,"-") -> 0.042162162 | O27: =IFERROR(B27/B$31,"-") -> 0.053286267
A28: Long-Term Unearned Revenue | B28: 163 | C28: 202 | D28: 218 | E28: 573 | F28: 976 | J28: Long-Term Unearned Revenue | K28: =IFERROR(F28/F$31,"-") -> 0.030241061 | L28: =IFERROR(E28/E$31,"-") -> 0.025186813 | M28: =IFERROR(D28/D$31,"-") -> 0.011424978 | N28: =IFERROR(C28/C$31,"-") -> 0.011493599 | O28: =IFERROR(B28/B$31,"-") -> 0.013699781
A29: Long-Term Deferred Tax Liabilities | B29: 241 | C29: 245 | D29: 247 | E29: 462 | F29: 886 | J29: Long-Term Deferred Tax Liabilities | K29: =IFERROR(F29/F$31,"-") -> 0.027452438 | L29: =IFERROR(E29/E$31,"-") -> 0.020307692 | M29: =IFERROR(D29/D$31,"-") -> 0.012944814 | N29: =IFERROR(C29/C$31,"-") -> 0.013940256 | O29: =IFERROR(B29/B$31,"-") -> 0.020255505
... A31: Total Liabilities | B31: 11898 | C31: 17575 | D31: 19081 | E31: 22750 | F31: 32274 | J31: Total Liabilities | K31: =IFERROR(F31/F$31,"-") -> 1 | L31: =IFERROR(E31/E$31,"-") -> 1 | M31: =IFERROR(D31/D$31,"-") -> 1 | N31: =IFERROR(C31/C$31,"-") -> 1 | O31: =IFERROR(B31/B$31,"-") -> 1
A32: Common Stock | B32: 3 | C32: 3 | D32: 2 | E32: 25 | F32: 24 | J32: Common Stock | K32: =IFERROR(F32/F$37,"-") -> 0.00030254516 | L32: =IFERROR(E32/E$37,"-") -> 0.00058169296 | M32: =IFERROR(D32/D$37,"-") -> 9.0493643e-05 | N32: =IFERROR(C32/C$37,"-") -> 0.0001127311 | O32: =IFERROR(B32/B$37,"-") -> 0.00017758835
A33: Additional Paid-In Capital | B33: 8719 | C33: 10385 | D33: 11971 | E33: 13109 | F33: 11237 | J33: Additional Paid-In Capital | K33: =IFERROR(F33/F$37,"-") -> 0.14165417 | L33: =IFERROR(E33/E$37,"-") -> 0.30501652 | M33: =IFERROR(D33/D$37,"-") -> 0.5416497 | N33: =IFERROR(C33/C$37,"-") -> 0.39023749 | O33: =IFERROR(B33/B$37,"-") -> 0.51613094
A34: Retained Earnings | B34: 18908 | C34: 16235 | D34: 10171 | E34: 29817 | F34: 68038 | J34: Retained Earnings | K34: =IFERROR(F34/F$37,"-") -> 0.85769032 | L34: =IFERROR(E34/E$37,"-") -> 0.69377356 | M34: =IFERROR(D34/D$37,"-") -> 0.46020542 | N34: =IFERROR(C34/C$37,"-") -> 0.61006313 | O34: =IFERROR(B34/B$37,"-") -> 1.1192802
A35: Treasury Stock | B35: -10756 | C35: 0 | D35: 0 | E35: 0 | F35: 0 | J35: Treasury Stock | K35: =IFERROR(F35/F$37,"-") -> 0 | L35: =IFERROR(E35/E$37,"-") -> 0 | M35: =IFERROR(D35/D$37,"-") -> 0 | N35: =IFERROR(C35/C$37,"-") -> 0 | O35: =IFERROR(B35/B$37,"-") -> -0.63671343
A36: Comprehensive Income & Other | B36: 19 | C36: -11 | D36: -43 | E36: 27 | F36: 28 | J36: Comprehensive Income & Other | K36: =IFERROR(F36/F$37,"-") -> 0.00035296935 | L36: =IFERROR(E36/E$37,"-") -> 0.0006282284 | M36: =IFERROR(D36/D$37,"-") -> -0.0019456133 | N36: =IFERROR(C36/C$37,"-") -> -0.00041334736 | O36: =IFERROR(B36/B$37,"-") -> 0.0011247262
A37: Shareholders' Equity | B37: 16893 | C37: 26612 | D37: 22101 | E37: 42978 | F37: 79327 | J37: Shareholders' Equity | K37: =IFERROR(F37/F$37,"-") -> 1 | L37: =IFERROR(E37/E$37,"-") -> 1 | M37: =IFERROR(D37/D$37,"-") -> 1 | N37: =IFERROR(C37/C$37,"-") -> 1 | O37: =IFERROR(B37/B$37,"-") -> 1
A38: Total Liabilities & Equity | B38: 28791 | C38: 44187 | D38: 41182 | E38: 65728 | F38: 111601
A40: Check | B40: =F38-F17 -> 0 | C40: =E38-E17 -> 0 | D40: =D38-D17 -> 0 | E40: =C38-C17 -> 0 | F40: =B38-B17 -> 0

Sheet 03_Historical_CF
A1: Cash Flow statement | I1: Cash Flow statement | T1: NVIDIA Corporation Common-Size Cash Flow Statement: Percentage of Inflows/Outflows Approach
B2: 2023 | C2: 2024 | D2: 2025 | J2: 2023 | K2: 2024 | L2: 2025
A3: Cash flows from operating activities: | I3: Cash flows from operating activities: | L3: % of net revenue
A4: Net income | B4: 4368 | C4: 29760 | D4: 72880 | I4: Net income | J4: =IFERROR(B4/'01_Historical_IS'!E$3," _ ") -> 0.16193371 | K4: =IFERROR(C4/'01_Historical_IS'!F$3," _ ") -> 0.48849348 | L4: =IFERROR(D4/'01_Historical_IS'!G$3," _ ") -> 0.55848027
A5: Adjustments to reconcile net income to net cash provided by operating activities: | I5: Adjustments to reconcile net income to net cash provided by operating activities: | J5: =IFERROR(B5/'01_Historical_IS'!E$3," _ ") -> 0 | K5: =IFERROR(C5/'01_Historical_IS'!F$3," _ ") -> 0 | L5: =IFERROR(D5/'01_Historical_IS'!$G$3," _ ") -> 0
A6: Stock-based compensation expense | B6: 2709 | C6: 3549 | D6: 4737 | I6: Stock-based compensation expense | J6: =IFERROR(B6/'01_Historical_IS'!E$3," _ ") -> 0.10043004 | K6: =IFERROR(C6/'01_Historical_IS'!F$3," _ ") -> 0.058254818 | L6: =IFERROR(D6/'01_Historical_IS'!$G$3," _ ") -> 0.036299685
A7: Depreciation and amortization | B7: 1544 | C7: 1508 | D7: 1864 | I7: Depreciation and amortization | J7: =IFERROR(B7/'01_Historical_IS'!E$3," _ ") -> 0.057240305 | K7: =IFERROR(C7/'01_Historical_IS'!F$3," _ ") -> 0.024752963 | L7: =IFERROR(D7/'01_Historical_IS'!$G$3," _ ") -> 0.014283853
A8: Deferred income taxes | B8: -2164 | C8: -2489 | D8: -4477 | I8: Deferred income taxes | J8: =IFERROR(B8/'01_Historical_IS'!E$3," _ ") -> -0.080225402 | K8: =IFERROR(C8/'01_Historical_IS'!F$3," _ ") -> -0.04085552 | L8: =IFERROR(D8/'01_Historical_IS'!$G$3," _ ") -> -0.034307302
A9: (Gains) losses on non-marketable equity securities and publicly-held equity securities, net | B9: 45 | C9: -238 | D9: -1030 | I9: (Gains) losses on non-marketable equity securities and publicly-held equity securities, net | J9: =IFERROR(B9/'01_Historical_IS'!E$3," _ ") -> 0.0016682732 | K9: =IFERROR(C9/'01_Historical_IS'!F$3," _ ") -> -0.0039066347 | L9: =IFERROR(D9/'01_Historical_IS'!$G$3," _ ") -> -0.0078929018
A10: Acquisition termination cost | B10: 1353 | C10: 0 | D10: 0 | I10: Acquisition termination cost | J10: =IFERROR(B10/'01_Historical_IS'!E$3," _ ") -> 0.050159413 | K10: =IFERROR(C10/'01_Historical_IS'!F$3," _ ") -> 0 | L10: =IFERROR(D10/'01_Historical_IS'!$G$3," _ ") -> 0
A11: Other | B11: -7 | C11: -278 | D11: -502 | I11: Other | J11: =IFERROR(B11/'01_Historical_IS'!E$3," _ ") -> -0.00025950916 | K11: =IFERROR(C11/'01_Historical_IS'!F$3," _ ") -> -0.004563212 | L11: =IFERROR(D11/'01_Historical_IS'!$G$3," _ ") -> -0.0038468317
A12: Changes in operating assets and liabilities, net of acquisitions: | I12: Changes in operating assets and liabilities, net of acquisitions: | J12: =IFERROR(B12/'01_Historical_IS'!E$3," _ ") -> 0 | K12: =IFERROR(C12/'01_Historical_IS'!F$3," _ ") -> 0 | L12: =IFERROR(D12/'01_Historical_IS'!$G$3," _ ") -> 0
A13: Accounts receivable | B13: 822 | C13: -6172 | D13: -13063 | I13: Accounts receivable | J13: =IFERROR(B13/'01_Historical_IS'!E$3," _ ") -> 0.03047379 | K13: =IFERROR(C13/'01_Historical_IS'!F$3," _ ") -> -0.10130987 | L13: =IFERROR(D13/'01_Historical_IS'!$G$3," _ ") -> -0.10010192
A14: Inventories | B14: -2554 | C14: -98 | D14: -4781 | I14: Inventories | J14: =IFERROR(B14/'01_Historical_IS'!E$3," _ ") -> -0.09468377 | K14: =IFERROR(C14/'01_Historical_IS'!F$3," _ ") -> -0.0016086143 | L14: =IFERROR(D14/'01_Historical_IS'!$G$3," _ ") -> -0.036636858
A15: Prepaid expenses and other assets | B15: -1517 | C15: -1522 | D15: -395 | I15: Prepaid expenses and other assets | J15: =IFERROR(B15/'01_Historical_IS'!E$3," _ ") -> -0.056239342 | K15: =IFERROR(C15/'01_Historical_IS'!F$3," _ ") -> -0.024982765 | L15: =IFERROR(D15/'01_Historical_IS'!$G$3," _ ") -> -0.0030268895
A16: Accounts payable | B16: -551 | C16: 1531 | D16: 3357 | I16: Accounts payable | J16: =IFERROR(B16/'01_Historical_IS'!E$3," _ ") -> -0.020427078 | K16: =IFERROR(C16/'01_Historical_IS'!F$3," _ ") -> 0.025130495 | L16: =IFERROR(D16/'01_Historical_IS'!$G$3," _ ") -> 0.025724729
A17: Accrued and other current liabilities | B17: 1341 | C17: 2025 | D17: 4278 | I17: Accrued and other current liabilities | J17: =IFERROR(B17/'01_Historical_IS'!E$3," _ ") -> 0.04971454 | K17: =IFERROR(C17/'01_Historical_IS'!F$3," _ ") -> 0.033239224 | L17: =IFERROR(D17/'01_Historical_IS'!$G$3," _ ") -> 0.032782363
A18: Other long-term liabilities | B18: 252 | C18: 514 | D18: 1221 | I18: Other long-term liabilities | J18: =IFERROR(B18/'01_Historical_IS'!E$3," _ ") -> 0.0093423297 | K18: =IFERROR(C18/'01_Historical_IS'!F$3," _ ") -> 0.0084370178 | L18: =IFERROR(D18/'01_Historical_IS'!$G$3," _ ") -> 0.0093565369
A19: Net cash provided by operating activities | B19: 5641 | C19: 28090 | D19: 64089 | I19: Net cash provided by operating activities | J19: =IFERROR(B19/'01_Historical_IS'!E$3," _ ") -> 0.20912731 | K19: =IFERROR(C19/'01_Historical_IS'!F$3," _ ") -> 0.46108138 | L19: =IFERROR(D19/'01_Historical_IS'!$G$3," _ ") -> 0.49111474
A20: Cash flows from investing activities: | I20: Cash flows from investing activities: | J20: =IFERROR(B20/'01_Historical_IS'!E$3," _ ") -> 0 | K20: =IFERROR(C20/'01_Historical_IS'!F$3," _ ") -> 0 | L20: =IFERROR(D20/'01_Historical_IS'!$G$3," _ ") -> 0
A21: Proceeds from maturities of marketable securities | B21: 19425 | C21: 9732 | D21: 11195 | I21: Proceeds from maturities of marketable securities | J21: =IFERROR(B21/'01_Historical_IS'!E$3," _ ") -> 0.72013791 | K21: =IFERROR(C21/'01_Historical_IS'!F$3," _ ") -> 0.15974525 | L21: =IFERROR(D21/'01_Historical_IS'!$G$3," _ ") -> 0.085787413
A22: Proceeds from sales of marketable securities | B22: 1806 | C22: 50 | D22: 495 | I22: Proceeds from sales of marketable securities | J22: =IFERROR(B22/'01_Historical_IS'!E$3," _ ") -> 0.066953362 | K22: =IFERROR(C22/'01_Historical_IS'!F$3," _ ") -> 0.00082072158 | L22: =IFERROR(D22/'01_Historical_IS'!$G$3," _ ") -> 0.0037931906
A23: Proceeds from sales of non-marketable equity securities | B23: 8 | C23: 1 | D23: 171 | I23: Proceeds from sales of non-marketable equity securities | J23: =IFERROR(B23/'01_Historical_IS'!E$3," _ ") -> 0.00029658189 | K23: =IFERROR(C23/'01_Historical_IS'!F$3," _ ") -> 1.6414432e-05 | L23: =IFERROR(D23/'01_Historical_IS'!$G$3," _ ") -> 0.001310375
A24: Purchases of marketable securities | B24: -11897 | C24: -18211 | D24: -26575 | I24: Purchases of marketable securities | J24: =IFERROR(B24/'01_Historical_IS'!E$3," _ ") -> -0.44105435 | K24: =IFERROR(C24/'01_Historical_IS'!F$3," _ ") -> -0.29892321 | L24: =IFERROR(D24/'01_Historical_IS'!$G$3," _ ") -> -0.20364453
A25: Purchases related to property and equipment and intangible assets (capEX) | B25: -1833 | C25: -1069 | D25: -3236 | I25: Purchases related to property and equipment and intangible assets | J25: =IFERROR(B25/'01_Historical_IS'!E$3," _ ") -> -0.067954326 | K25: =IFERROR(C25/'01_Historical_IS'!F$3," _ ") -> -0.017547027 | L25: =IFERROR(D25/'01_Historical_IS'!$G$3," _ ") -> -0.024797505
A26: Purchases of non-marketable equity securities | B26: -85 | C26: -862 | D26: -1486 | I26: Purchases of non-marketable equity securities | J26: =IFERROR(B26/'01_Historical_IS'!E$3," _ ") -> -0.0031511826 | K26: =IFERROR(C26/'01_Historical_IS'!F$3," _ ") -> -0.01414924 | L26: =IFERROR(D26/'01_Historical_IS'!$G$3," _ ") -> -0.011387235
A27: Acquisitions, net of cash acquired | B27: -49 | C27: -83 | D27: -1007 | I27: Acquisitions, net of cash acquired | J27: =IFERROR(B27/'01_Historical_IS'!E$3," _ ") -> -0.0018165641 | K27: =IFERROR(C27/'01_Historical_IS'!F$3," _ ") -> -0.0013623978 | L27: =IFERROR(D27/'01_Historical_IS'!$G$3," _ ") -> -0.0077166525
A28: Other | B28: 0 | C28: -124 | D28: 22 | I28: Other | J28: =IFERROR(B28/'01_Historical_IS'!E$3," _ ") -> 0 | K28: =IFERROR(C28/'01_Historical_IS'!F$3," _ ") -> -0.0020353895 | L28: =IFERROR(D28/'01_Historical_IS'!$G$3," _ ") -> 0.00016858625
A29: Net cash provided by (used in) investing activities | B29: 7375 | C29: -10566 | D29: -20421 | I29: Net cash provided by (used in) investing activities | J29: =IFERROR(B29/'01_Historical_IS'!E$3," _ ") -> 0.27341143 | K29: =IFERROR(C29/'01_Historical_IS'!F$3," _ ") -> -0.17343488 | L29: =IFERROR(D29/'01_Historical_IS'!$G$3," _ ") -> -0.15648636
A30: Cash flows from financing activities: | I30: Cash flows from financing activities: | J30: =IFERROR(B30/'01_Historical_IS'!E$3," _ ") -> 0 | K30: =IFERROR(C30/'01_Historical_IS'!F$3," _ ") -> 0 | L30: =IFERROR(D30/'01_Historical_IS'!$G$3," _ ") -> 0
A31: Proceeds related to employee stock plans | B31: 355 | C31: 403 | D31: 490 | I31: Proceeds related to employee stock plans | J31: =IFERROR(B31/'01_Historical_IS'!E$3," _ ") -> 0.013160822 | K31: =IFERROR(C31/'01_Historical_IS'!F$3," _ ") -> 0.0066150159 | L31: =IFERROR(D31/'01_Historical_IS'!$G$3," _ ") -> 0.0037548756
A32: Payments related to repurchases of common stock (buyback) | B32: -10039 | C32: -9533 | D32: -33706 | I32: Payments related to repurchases of common stock | J32: =IFERROR(B32/'01_Historical_IS'!E$3," _ ") -> -0.3721732 | K32: =IFERROR(C32/'01_Historical_IS'!F$3," _ ") -> -0.15647878 | L32: =IFERROR(D32/'01_Historical_IS'!$G$3," _ ") -> -0.25828946
A33: Payments related to tax on restricted stock units | B33: -1475 | C33: -2783 | D33: -6930 | I33: Payments related to tax on restricted stock units | J33: =IFERROR(B33/'01_Historical_IS'!E$3," _ ") -> -0.054682287 | K33: =IFERROR(C33/'01_Historical_IS'!F$3," _ ") -> -0.045681363 | L33: =IFERROR(D33/'01_Historical_IS'!$G$3," _ ") -> -0.053104669
A34: Repayment of debt | B34: 0 | C34: -1250 | D34: -1250 | I34: Repayment of debt | J34: =IFERROR(B34/'01_Historical_IS'!E$3," _ ") -> 0 | K34: =IFERROR(C34/'01_Historical_IS'!F$3," _ ") -> -0.020518039 | L34: =IFERROR(D34/'01_Historical_IS'!$G$3," _ ") -> -0.0095787643
A35: Dividends paid | B35: -398 | C35: -395 | D35: -834 | I35: Dividends paid | J35: =IFERROR(B35/'01_Historical_IS'!E$3," _ ") -> -0.014754949 | K35: =IFERROR(C35/'01_Historical_IS'!F$3," _ ") -> -0.0064837005 | L35: =IFERROR(D35/'01_Historical_IS'!$G$3," _ ") -> -0.0063909515
A36: Principal payments on property and equipment and intangible assets | B36: -58 | C36: -74 | D36: -129 | I36: Principal payments on property and equipment and intangible assets | J36: =IFERROR(B36/'01_Historical_IS'!E$3," _ ") -> -0.0021502187 | K36: =IFERROR(C36/'01_Historical_IS'!F$3," _ ") -> -0.0012146679 | L36: =IFERROR(D36/'01_Historical_IS'!$G$3," _ ") -> -0.00098852847
A37: Other | B37: -2 | C37: -1 | D37: 0 | I37: Other | J37: =IFERROR(B37/'01_Historical_IS'!E$3," _ ") -> -7.4145473e-05 | K37: =IFERROR(C37/'01_Historical_IS'!F$3," _ ") -> -1.6414432e-05 | L37: =IFERROR(D37/'01_Historical_IS'!$G$3," _ ") -> 0
A38: Net cash used in financing activities | B38: -11617 | C38: -13633 | D38: -42359 | I38: Net cash used in financing activities | J38: =IFERROR(B38/'01_Historical_IS'!E$3," _ ") -> -0.43067398 | K38: =IFERROR(C38/'01_Historical_IS'!F$3," _ ") -> -0.22377795 | L38: =IFERROR(D38/'01_Historical_IS'!$G$3," _ ") -> -0.3245975
A39: Change in cash and cash equivalents ( Net Cash Flow ) | B39: 1399 | C39: 3891 | D39: 1309 | I39: Change in cash and cash equivalents | J39: =IFERROR(B39/'01_Historical_IS'!E$3," _ ") -> 0.051864759 | K39: =IFERROR(C39/'01_Historical_IS'!F$3," _ ") -> 0.063868553 | L39: =IFERROR(D39/'01_Historical_IS'!$G$3," _ ") -> 0.010030882
A40: Cash and cash equivalents at beginning of period | B40: 1990 | C40: 3389 | D40: 7280 | I40: Cash and cash equivalents at beginning of period | J40: =IFERROR(B40/'01_Historical_IS'!E$3," _ ") -> 0.073774746 | K40: =IFERROR(C40/'01_Historical_IS'!F$3," _ ") -> 0.055628509 | L40: =IFERROR(D40/'01_Historical_IS'!$G$3," _ ") -> 0.055786723
...

Sheet 04a_Projection_IS
A2: Revenue Growth Analysis | N2: Margin Analysis
A3: ($ in millions) | B3: 2021 | C3: 2022 | D3: 2023 | E3: 2024 | F3: 2025 | G3: 2026F | H3: 2027F | I3: 2028F | J3: 2029F | K3: 2030F | N3: ($ in millions) | O3: 2020 | P3: 2021 | Q3: 2022 | R3: 2023 | S3: 2024 | T3: 2025 | U3: 2026F | V3: 2027F | W3: 2028F | X3: 2029F | Y3: 2030F
A5: Data Center revenue | B5: 6696 | C5: 10613 | D5: 15005 | E5: 47525 | F5: 115186 | G5: =90805+50000+54000 -> 194805 | H5: =G5*(1+H7) -> 276623.1 | I5: =H5*(1+I7) -> 351311.34 | J5: =I5*(1+J7) -> 407521.15 | K5: =J5*(1+K7) -> 497175.8 | N5: Gross Margin, % | O5: ='01_Historical_IS'!B5/'01_Historical_IS'!B3 -> 0.61989375 | P5: ='01_Historical_IS'!C5/'01_Historical_IS'!C3 -> 0.62344828 | Q5: ='01_Historical_IS'!D5/'01_Historical_IS'!D3 -> 0.64929033 | R5: ='01_Historical_IS'!E5/'01_Historical_IS'!E3 -> 0.56928894 | S5: ='01_Historical_IS'!F5/'01_Historical_IS'!F3 -> 0.72717573 | T5: ='01_Historical_IS'!G5/'01_Historical_IS'!G3 -> 0.74988697
A6: Y/Y Growth rate in Data center revenue | C6: =(C5/B5)-1 -> 0.58497611 | D6: =(D5/C5)-1 -> 0.41383209 | E6: =(E5/D5)-1 -> 2.1672776 | F6: =(F5/E5)-1 -> 1.4236928 | N6: Base case | U6: =T5+2% -> 0.76988697 | V6: =U6+2% -> 0.78988697 | W6: =V6+2% -> 0.80988697 | X6: =W6+2% -> 0.82988697 | Y6: =X6+2% -> 0.84988697
A7: Base case | G7: =69% -> 0.69 | H7: 0.42 | I7: 0.27 | J7: 0.16 | K7: 0.22 | N7: Upside case | U7: =U6+5% -> 0.81988697 | V7: =V6+5% -> 0.83988697 | W7: =W6+5% -> 0.85988697 | X7: =X6+5% -> 0.87988697 | Y7: =Y6+5% -> 0.89988697
A8: Upside case | G8: 0.95 | H8: 0.55 | I8: 0.35 | J8: 0.22 | K8: 0.42 | N8: Downside case | U8: 0.66 | V8: 0.655 | W8: 0.65 | X8: 0.65 | Y8: 0.645
A9: Downside case | G9: 0.5 | H9: 0.12 | I9: 0.04 | J9: -0.05 | K9: 0.02
N10: R&D Margin, % | O10: ='01_Historical_IS'!B8/'01_Historical_IS'!B3 -> 0.25911339 | P10: ='01_Historical_IS'!C8/'01_Historical_IS'!C3 -> 0.23532234 | Q10: ='01_Historical_IS'!D8/'01_Historical_IS'!D3 -> 0.19573456 | R10: ='01_Historical_IS'!E8/'01_Historical_IS'!E3 -> 0.27207681 | S10: ='01_Historical_IS'!F8/'01_Historical_IS'!F3 -> 0.14239519 | T10: ='01_Historical_IS'!G8/'01_Historical_IS'!G3 -> 0.098960129
A11: Gaming revenue | B11: 7759 | C11: 12462 | D11: 9067 | E11: 10447 | F11: 11350 | G11: =F11*(1+G13) -> 11917.5 | H11: =G11*(1+H13) -> 12275.025 | I11: =H11*(1+I13) -> 12520.525 | J11: =I11*(1+J13) -> 12770.936 | K11: =J11*(1+K13) -> 13154.064 | N11: Base case | U11: 0.095 | V11: 0.093 | W11: 0.09 | X11: 0.088 | Y11: 0.085
A12: Y/Y Growth rate in Gaming revenue | C12: =(C11/B11)-1 -> 0.60613481 | D12: =(D11/C11)-1 -> -0.27242818 | E12: =(E11/D11)-1 -> 0.15220029 | F12: =(F11/E11)-1 -> 0.086436298 | N12: Upside case | U12: 0.088 | V12: 0.085 | W12: 0.083 | X12: 0.08 | Y12: 0.078
A13: Base case | G13: 0.05 | H13: 0.03 | I13: 0.02 | J13: 0.02 | K13: 0.03 | N13: Downside case | U13: 0.105 | V13: 0.11 | W13: 0.11 | X13: 0.105 | Y13: 0.1
A14: Upside case | G14: 0.15 | H14: 0.1 | I14: 0.08 | J14: 0.05 | K14: 0.07
A15: Downside case | G15: -0.05 | H15: -0.05 | I15: -0.04 | J15: -0.05 | K15: 0.02 | N15: SG&A Margin, % | O15: ='01_Historical_IS'!B9/'01_Historical_IS'!B3 -> 0.10010991 | P15: ='01_Historical_IS'!C9/'01_Historical_IS'!C3 -> 0.11634183 | Q15: ='01_Historical_IS'!D9/'01_Historical_IS'!D3 -> 0.080478561 | R15: ='01_Historical_IS'!E9/'01_Historical_IS'!E3 -> 0.090457478 | S15: ='01_Historical_IS'!F9/'01_Historical_IS'!F3 -> 0.043563901 | T15: ='01_Historical_IS'!G9/'01_Historical_IS'!G3 -> 0.026751573
N16: Base case | U16: 0.025 | V16: 0.024 | W16: 0.023 | X16: 0.022 | Y16: 0.022
A17: Professional Visualization revenue | B17: 1053 | C17: 2111 | D17: 1544 | E17: 1553 | F17: 1878 | G17: =F17*(1+G19) -> 1990.68 | H17: =G17*(1+H19) -> 2130.0276 | I17: =H17*(1+I19) -> 2236.529 | J17: =I17*(1+J19) -> 2325.9901 | K17: =J17*(1+K19) -> 2442.2896 | N17: Upside case | U17: 0.024 | V17: 0.022 | W17: 0.021 | X17: 0.02 | Y17: 0.02
A18: Y/Y Growth rate in Professional Visualization revenue | C18: =(C17/B17)-1 -> 1.0047483 | D18: =(D17/C17)-1 -> -0.26859308 | E18: =(E17/D17)-1 -> 0.0058290155 | F18: =(F17/E17)-1 -> 0.20927238 | N18: Downside case | U18: 0.028 | V18: 0.03 | W18: 0.031 | X18: 0.03 | Y18: 0.03
A19: Base case | G19: 0.06 | H19: 0.07 | I19: 0.05 | J19: 0.04 | K19: 0.05
A20: Upside case | G20: 0.15 | H20: 0.12 | I20: 0.1 | J20: 0.1 | K20: 0.11
A21: Downside case | G21: -0.02 | H21: 0 | I21: -0.03 | J21: -0.02 | K21: 0.02
A23: Automotive revenue | B23: 536 | C23: 566 | D23: 903 | E23: 1091 | F23: 1694 | G23: =F23*(1+G25) -> 2456.3 | H23: =G23*(1+H25) -> 3684.45 | I23: =H23*(1+I25) -> 4974.0075 | J23: =I23*(1+J25) -> 6267.2494 | K23: =J23*(1+K25) -> 8460.7868
A24: Y/Y Growth rate Automotive revenue | C24: =(C23/B23)-1 -> 0.055970149 | D24: =(D23/C23)-1 -> 0.59540636 | E24: =(E23/D23)-1 -> 0.20819491 | F24: =(F23/E23)-1 -> 0.55270394 | M24: % | N24: 2021 | O24: 2022 | P24: 2023 | Q24: 2024 | R24: 2025
A25: Base case | G25: 0.45 | H25: 0.5 | I25: 0.35 | J25: 0.26 | K25: 0.35 | M25: Data Center revenue | N25: =B5/B35 -> 0.40155922 | O25: =C5/C35 -> 0.39433009 | P25: =D5/D35 -> 0.55627641 | Q25: =E5/E35 -> 0.78009586 | R25: =F5/F35 -> 0.88267163
A26: Upside case | G26: 0.65 | H26: 1 | I26: 0.5 | J26: 0.42 | K26: 0.5 | M26: Gaming revenue | N26: =B11/B35 -> 0.46530735 | O26: =C11/C35 -> 0.46303039 | P26: =D11/D35 -> 0.3361385 | Q26: =E11/E35 -> 0.17148157 | R26: =F11/F35 -> 0.08697518
A27: Downside case | G27: 0.1 | H27: 0.05 | I27: 0.05 | J27: 0.03 | K27: 0.07 | M27: Professional Visualization revenue | N27: =B17/B35 -> 0.063148426 | O27: =C17/C35 -> 0.078435015 | P27: =D17/D35 -> 0.057240305 | Q27: =E17/E35 -> 0.025491612 | R27: =F17/F35 -> 0.014391135
M28: Automotive revenue | N28: =B23/B35 -> 0.032143928 | O28: =C23/C35 -> 0.021029947 | P28: =D23/D35 -> 0.033476681 | Q28: =E23/E35 -> 0.017908145 | R28: =F23/F35 -> 0.012981141
A29: OEM and Other revenue | B29: 631 | C29: 1162 | D29: 455 | E29: 306 | F29: 389 | G29: =F29*(1+G31) -> 396.78 | H29: =G29*(1+H31) -> 408.6834 | I29: =H29*(1+I31) -> 416.85707 | J29: =I29*(1+J31) -> 425.19421 | K29: =J29*(1+K31) -> 437.95004 | M29: OEM and Other revenue | N29: =B29/B35 -> 0.037841079 | O29: =C29/C35 -> 0.043174556 | P29: =D29/D35 -> 0.016868095 | Q29: =E29/E35 -> 0.0050228161 | R29: =F29/F35 -> 0.0029809114
A30: Y/Y Growth rate in OEM and Other revenue | C30: =(C29/B29)-1 -> 0.84152139 | D30: =(D29/C29)-1 -> -0.60843373 | E30: =(E29/D29)-1 -> -0.32747253 | F30: =(F29/E29)-1 -> 0.27124183
A31: Base case | G31: 0.02 | H31: 0.03 | I31: 0.02 | J31: 0.02 | K31: 0.03
A32: Upside case | G32: 0.1 | H32: 0.12 | I32: 0.08 | J32: 0.06 | K32: 0.07
A33: Downside case | G33: -0.05 | H33: -0.03 | I33: -0.04 | J33: -0.03 | K33: -0.05
A35: Total Revenue | B35: =B5+B11+B17+B23+B29 -> 16675 | C35: =C5+C11+C17+C23+C29 -> 26914 | D35: =D5+D11+D17+D23+D29 -> 26974 | E35: =E5+E11+E17+E23+E29 -> 60922 | F35: =F5+F11+F17+F23+F29 -> 130497 | G35: =G5+G11+G17+G23+G29 -> 211566.26 | H35: =H5+H11+H17+H23+H29 -> 295121.29 | I35: =I5+I11+I17+I23+I29 -> 371459.26 | ... K35: =K5+K11+K17+K23+K29 -> 521670.89
A36: Y/Y Growth rate in Total revenue | C36: =(C35/B35)-1 -> 0.61403298 | D36: =(D35/C35)-1 -> 0.002229323 | E36: =(E35/D35)-1 -> 1.2585453 | F36: =(F35/E35)-1 -> 1.1420341 | G36: =(G35/F35)-1 -> 0.62123466 | H36: =(H35/G35)-1 -> 0.3949355 | I36: =(I35/H35)-1 -> 0.25866643 | J36: =(J35/I35)-1 -> 0.15574054 | K36: =(K35/J35)-1 -> 0.21513653
A41: Assumptions of Assumed Yield ( % return on investments)
B42: 2026 F | C42: 2027 F | D42: 2028 F | E42: 2029 F | F42: 2030 F | H42: Cash & Short-Term Investments % of revenue
A43: Assumed Yield, % | I43: 2026 F | J43: 2027 F | K43: 2028 F | L43: 2029 F | M43: 2030 F
A44: Base case | B44: 0.0345 | C44: 0.0325 | D44: 0.0325 | E44: 0.031 | F44: 0.031 | H44: %
A45: Upside case | B45: =B44-0.5% -> 0.0295 | C45: =C44-0.5% -> 0.0275 | D45: =D44-0.5% -> 0.0275 | E45: =E44-0.5% -> 0.026 | F45: =F44-0.5% -> 0.026 | H45: Base case | I45: 0.28 | J45: 0.25 | K45: 0.23 | L45: 0.22 | M45: 0.21
A46: Downside case | B46: =B44+0.5% -> 0.0395 | C46: =C44+0.5% -> 0.0375 | D46: =D44+0.5% -> 0.0375 | E46: =E44+0.5% -> 0.036 | F46: =F44+0.5% -> 0.036 | H46: Upside case | I46: 0.3 | J46: 0.28 | K46: 0.27 | L46: 0.26 | M46: 0.25
H47: Downside case | I47: 0.25 | J47: 0.22 | K47: 0.2 | L47: 0.19 | M47: 0.18
A50: Interest Income projections
...

Sheet 04b_Projection_BS
A1: Balance Sheet | B1: Historical | G1: Projected
A2: ($ in millions) | B2: 2021 | C2: 2022 | D2: 2023 | E2: 2024 | F2: 2025 | G2: 2026F | H2: 2027F | I2: 2028F | J2: 2029F | K2: 2030F
A3: Cash & Short-Term Investments | B3: 11561 | C3: 21208 | D3: 13296 | E3: 25984 | F3: 43210 | G3: ='04a_Projection_IS'!G53 -> 59238.553 | H3: ='04a_Projection_IS'!H53 -> 73780.321 | I3: ='04a_Projection_IS'!I53 -> 85435.629 | J3: ='04a_Projection_IS'!J53 -> 94448.315 | K3: ='04a_Projection_IS'!K53 -> 109550.89
A4: Receivables | B4: 2429 | C4: 4650 | D4: 3827 | E4: 9999 | F4: 23065 | G4: ='09_WorkingCapital'!G9 -> 36814.144 | H4: ='09_WorkingCapital'!H9 -> 50544.805 | I4: ='09_WorkingCapital'!I9 -> 62601.352 | J4: ='09_WorkingCapital'!J9 -> 71174.728 | K4: ='09_WorkingCapital'!K9 -> 85057.776
A5: Inventory | B5: 1826 | C5: 2605 | D5: 5159 | E5: 5282 | F5: 10080 | G5: ='09_WorkingCapital'!G10 -> 14671.937 | H5: ='09_WorkingCapital'!H10 -> 17838.156 | I5: ='09_WorkingCapital'!I10 -> 19347.738 | J5: ='09_WorkingCapital'!J10 -> 19008.15 | K5: ='09_WorkingCapital'!K10 -> 19309.216
A6: Prepaid Expenses | B6: 239 | C6: 366 | D6: 791 | E6: 3080 | F6: 3771 | G6: ='09_WorkingCapital'!G11 -> 5074.263 | H6: ='09_WorkingCapital'!H11 -> 5865.4371 | I6: ='09_WorkingCapital'!I11 -> 5870.9843 | J6: ='09_WorkingCapital'!J11 -> 5666.8989 | K6: ='09_WorkingCapital'!K11 -> 5581.8786
A7: Total Current Assets | B7: 16055 | C7: 28829 | D7: 23073 | E7: 44345 | F7: 80126 | G7: =SUM(G3:G6) -> 115798.9 | H7: =SUM(H3:H6) -> 148028.72 | I7: =SUM(I3:I6) -> 173255.7 | J7: =SUM(J3:J6) -> 190298.09 | K7: =SUM(K3:K6) -> 219499.76
A8: Property, Plant & Equipment | B8: ='02_Historical_BS'!B11 -> 2149 | C8: ='02_Historical_BS'!C11 -> 2778 | D8: ='02_Historical_BS'!D11 -> 3807 | E8: ='02_Historical_BS'!E11 -> 3914 | F8: ='02_Historical_BS'!F11 -> 6283 | G8: ='12_FixedAssets'!I15 -> 9937.7902 | H8: ='12_FixedAssets'!J15 -> 17492.895 | I8: ='12_FixedAssets'!K15 -> 27494.62 | J8: ='12_FixedAssets'!L15 -> 38164.672 | K8: ='12_FixedAssets'!M15 -> 50711.1
A9: Operating lease assets | B9: 707 | C9: 829 | D9: 1038 | E9: 1346 | F9: 1793 | G9: =F9 -> 1793 | H9: =G9 -> 1793 | I9: =H9 -> 1793 | J9: =I9 -> 1793 | K9: =J9 -> 1793
A10: Goodwill | B10: 4193 | C10: 4349 | D10: 4372 | E10: 4430 | F10: 5188 | G10: =F10 -> 5188 | H10: =G10 -> 5188 | I10: =H10 -> 5188 | J10: =I10 -> 5188 | K10: =J10 -> 5188
A11: Intangible Assets , net | B11: 2737 | C11: 2339 | D11: 1676 | E11: 1112 | F11: 807 | G11: ='12_FixedAssets'!I27 -> 1214.6385 | H11: ='12_FixedAssets'!J27 -> 2111.9043 | I11: ='12_FixedAssets'!K27 -> 3498.8829 | J11: ='12_FixedAssets'!L27 -> 5013.4008 | K11: ='12_FixedAssets'!M27 -> 6756.215
A12: Other Assets | B12: ='02_Historical_BS'!B15+'02_Historical_BS'!B16 -> 2950 | C12: ='02_Historical_BS'!C15+'02_Historical_BS'!C16 -> 5063 | D12: ='02_Historical_BS'!D15+'02_Historical_BS'!D16 -> 7216 | E12: ='02_Historical_BS'!E15+'02_Historical_BS'!E16 -> 10581 | F12: ='02_Historical_BS'!F15+'02_Historical_BS'!F16 -> 17404 | G12: =F12 -> 17404 | H12: =G12 -> 17404 | I12: =H12 -> 17404 | J12: =I12 -> 17404 | K12: =J12 -> 17404
A13: Total Assets | B13: =SUM(B7:B12) -> 28791 | C13: 44187 | D13: 41182 | E13: 65728 | F13: 111601 | G13: =G7+G8+G9+G10+G11+G12 -> 151336.33 | H13: =H7+H8+H9+H10+H11+H12 -> 192018.52 | I13: =I7+I8+I9+I10+I11+I12 -> 228634.21 | J13: =J7+J8+J9+J10+J11+J12 -> 257861.16 | K13: =K7+K8+K9+K10+K11+K12 -> 301352.07
A14: Accounts Payable | B14: 1149 | C14: 1783 | D14: 1193 | E14: 2699 | F14: 6310 | G14: ='09_WorkingCapital'!B14 -> 1149 | H14: ='09_WorkingCapital'!C14 -> 1783 | I14: ='09_WorkingCapital'!D14 -> 1193 | J14: ='09_WorkingCapital'!E14 -> 2699 | K14: ='09_WorkingCapital'!F14 -> 6310
A15: Accrued Expenses | B15: 297 | C15: 409 | D15: 530 | E15: 675 | F15: 848 | G15: ='09_WorkingCapital'!B15 -> 2776 | H15: ='09_WorkingCapital'!C15 -> 2552 | I15: ='09_WorkingCapital'!D15 -> 5370 | J15: ='09_WorkingCapital'!E15 -> 7932 | K15: ='09_WorkingCapital'!F15 -> 11737
A16: Short-Term Debt | B16: 999 | C16: 0 | D16: 1250 | E16: 1250 | F16: 0 | G16: =-'13_DebtSchedule'!I7 -> 1000 | H16: =-'13_DebtSchedule'!J7 -> 0 | I16: =-'13_DebtSchedule'!K7 -> 1250 | J16: =-'13_DebtSchedule'!L7 -> 0 | K16: =-'13_DebtSchedule'!M7 -> 1500
A17: Current Portion of Leases | B17: 0 | C17: 144 | D17: 176 | E17: 228 | F17: 288 | G17: =G38 -> 530.25789 | H17: =H38 -> 772.51577 | I17: =I38 -> 1014.7737 | J17: =J38 -> 1257.0315 | K17: =K38 -> 1499.2894
A18: Current Income Taxes Payable | B18: 0 | C18: 132 | D18: 467 | E18: 296 | F18: 881 | G18: =G51 -> 1671.4297 | H18: =H51 -> 2312.0871 | I18: =I51 -> 3008.8684 | J18: =J51 -> 3462.2958 | K18: =K51 -> 4335.3636
A19: Other Current Liabilities | B19: ='02_Historical_BS'!B23+'02_Historical_BS'!B24 -> 1480 | C19: ='02_Historical_BS'!C23+'02_Historical_BS'!C24 -> 1867 | D19: ='02_Historical_BS'!D23+'02_Historical_BS'!D24 -> 2947 | E19: ='02_Historical_BS'!E23+'02_Historical_BS'!E24 -> 5483 | F19: ='02_Historical_BS'!F23+'02_Historical_BS'!F24 -> 9720 | G19: =G55 -> 9366.8572 | H19: =H55 -> 13544.462 | I19: =I55 -> 17649.805 | J19: =J55 -> 21328.095 | K19: =K55 -> 24848.653
A20: Total Current Liabilities | B20: 3925 | C20: 4335 | D20: 6563 | E20: 10631 | F20: 18047 | G20: =SUM(G14:G19) -> 16493.545 | H20: =SUM(H14:H19) -> 20964.065 | I20: =SUM(I14:I19) -> 29486.447 | J20: =SUM(J14:J19) -> 36678.423 | K20: =SUM(K14:K19) -> 50230.306
A21: Long-Term Debt | B21: 5964 | C21: 10946 | D21: 9703 | E21: 8459 | F21: 8463 | G21: ='13_DebtSchedule'!I8 -> 7463 | H21: ='13_DebtSchedule'!J8 -> 7463 | I21: ='13_DebtSchedule'!K8 -> 6213 | J21: ='13_DebtSchedule'!L8 -> 6213 | K21: ='13_DebtSchedule'!M8 -> 4713
A22: Long-Term Leases | B22: 634 | C22: 741 | D22: 902 | E22: 1119 | F22: 1519 | G22: =G39 -> 2796.7421 | H22: =H39 -> 4074.4842 | I22: =I39 -> 5352.2263 | J22: =J39 -> 6629.9685 | K22: =K39 -> 7907.7106
A23: Other Long-Term Liabilities | B23: ='02_Historical_BS'!B28+'02_Historical_BS'!B29+'02_Historical_BS'!B30 -> 1375 | C23: ='02_Historical_BS'!C28+'02_Historical_BS'!C29+'02_Historical_BS'!C30 -> 1553 | D23: ='02_Historical_BS'!D28+'02_Historical_BS'!D29+'02_Historical_BS'!D30 -> 1913 | E23: ='02_Historical_BS'!E28+'02_Historical_BS'!E29+'02_Historical_BS'!E30 -> 2541 | F23: ='02_Historical_BS'!F28+'02_Historical_BS'!F29+'02_Historical_BS'!F30 -> 4245 | G23: =F23 -> 4245 | H23: =G23 -> 4245 | I23: =H23 -> 4245 | J23: =I23 -> 4245 | K23: =J23 -> 4245
A24: Total Liabilities | B24: 11898 | C24: 17575 | D24: 19081 | E24: 22750 | F24: 32274 | G24: =SUM(G20:G23) -> 30998.287 | H24: =SUM(H20:H23) -> 36746.549 | I24: =SUM(I20:I23) -> 45296.673 | J24: =SUM(J20:J23) -> 53766.391 | K24: =SUM(K20:K23) -> 67096.017
A25: Common Stock | B25: 3 | C25: 3 | D25: 2 | E25: 25 | F25: 24 | G25: =F25 -> 24 | H25: =G25 -> 24 | I25: =H25 -> 24 | J25: =I25 -> 24 | K25: =J25 -> 24
A26: Additional Paid-In Capital | B26: 8719 | C26: 10385 | D26: 11971 | E26: 13109 | F26: 11237 | G26: =F26+E65 -> 16314.59 | H26: =G26+F65 -> 21921.895 | I26: =H26+G65 -> 28236.702 | J26: =I26+H65 -> 35105.67 | K26: =J26+I65 -> 43452.405
A27: Retained Earnings | B27: 18908 | C27: 16235 | D27: 10171 | E27: 29817 | F27: 68038 | G27: =G80 -> 186667.88 | H27: =H80 -> 357598.2 | I27: =I80 -> 580040.87 | J27: =J80 -> 846965.95 | K27: =K80 -> 1181200
A28: Treasury Stock | B28: -10756 | C28: 0 | D28: 0 | E28: 0 | F28: 0 | G28: =F28 -> 0 | H28: =G28 -> 0 | I28: =H28 -> 0 | J28: =I28 -> 0 | K28: =J28 -> 0
A29: Comprehensive Income & Other | B29: 19 | C29: -11 | D29: -43 | E29: 27 | F29: 28 | G29: =F29 -> 28 | H29: =G29 -> 28 | I29: =H29 -> 28 | J29: =I29 -> 28 | K29: =J29 -> 28
A30: Shareholders' Equity | B30: 16893 | C30: 26612 | D30: 22101 | E30: 42978 | F30: 79327 | G30: =SUM(G25:G29) -> 203034.47 | H30: =SUM(H25:H29) -> 379572.09 | I30: =SUM(I25:I29) -> 608329.57 | J30: =SUM(J25:J29) -> 882123.62 | K30: =SUM(K25:K29) -> 1224704.4
A31: Total Liabilities & Equity | B31: 28791 | C31: 44187 | D31: 41182 | E31: 65728 | F31: 111601 | G31: =G30+G24 -> 234032.76 | H31: =H30+H24 -> 416318.64 | I31: =I30+I24 -> 653626.24 | J31: =J30+J24 -> 935890.01 | K31: =K30+K24 -> 1291800.5
A33: Check | B33: =B13-B31 -> 0 | C33: =C13-C31 -> 0 | D33: =D13-D31 -> 0 | E33: =E13-E31 -> 0 | F33: =F13-F31 -> 0
A36: Leasing Model
B37: 2021 A | C37: 2022 A | D37: 2023 A | E37: 2024 A | F37: 2025 A | G37: 2026 F | H37: 2027 F | I37: 2028 F | J37: 2029 F | K37: 2030 F
A38: Current Portion of Leases | B38: =B17 -> 0 | C38: =C17 -> 144 | D38: =D17 -> 176 | E38: =E17 -> 228 | F38: =F17 -> 288 | G38: =G41*G40 -> 530.25789 | H38: =H41*H40 -> 772.51577 | I38: =I41*I40 -> 1014.7737 | J38: =J41*J40 -> 1257.0315 | K38: =K41*K40 -> 1499.2894
A39: Long-Term Leases | B39: =B22 -> 634 | C39: =C22 -> 741 | D39: =D22 -> 902 | E39: =E22 -> 1119 | F39: =F22 -> 1519 | G39: =G40-G38 -> 2796.7421 | H39: =H40-H38 -> 4074.4842 | I39: =I40-I38 -> 5352.2263 | J39: =J40-J38 -> 6629.9685 | K39: =K40-K38 -> 7907.7106
A40: Total of Leases | B40: =SUM(B38:B39) -> 634 | C40: =SUM(C38:C39) -> 885 | D40: =SUM(D38:D39) -> 1078 | E40: =SUM(E38:E39) -> 1347 | F40: =SUM(F38:F39) -> 1807 | G40: =G45 -> 3327 | H40: =H45 -> 4847 | I40: =I45 -> 6367 | J40: =J45 -> 7887 | K40: =K45 -> 9407
A41: Current Portion of Leases % | B41: =B38/B40 -> 0 | C41: =C38/C40 -> 0.16271186 | D41: =D38/D40 -> 0.16326531 | E41: =E38/E40 -> 0.16926503 | F41: =F38/F40 -> 0.15938019 | G41: =F41 -> 0.15938019 | H41: =G41 -> 0.15938019 | I41: =H41 -> 0.15938019 | J41: =I41 -> 0.15938019 | K41: =J41 -> 0.15938019
A43: Opening Lease Liability | B43: 0 | C43: =B45 -> 634 | D43: =C45 -> 885 | E43: =D45 -> 1078 | F43: =E45 -> 1347 | G43: =F45 -> 1807 | H43: =G45 -> 3327 | I43: =H45 -> 4847 | J43: =I45 -> 6367 | K43: =J45 -> 7887
A44: New Leases | B44: 0 | C44: =C45-C43 -> 251 | D44: =D45-D43 -> 193 | E44: =E45-E43 -> 269 | F44: =F45-F43 -> 460 | G44: =G47 -> 1520 | H44: =H47 -> 1520 | I44: =I47 -> 1520 | J44: =J47 -> 1520 | K44: =K47 -> 1520
...

Sheet 04c_Projection_CF
A1: Cash Flow statement
B2: 2023 | C2: 2024 | D2: 2025 | E2: 2026F | F2: 2027F | G2: 2028F | H2: 2029F | I2: 2030F
A3: Cash flows from operating activities:
A4: Net income | B4: 4368 | C4: 29760 | D4: 72880 | E4: ='04a_Projection_IS'!H97 -> 119828.16 | F4: ='04a_Projection_IS'!I97 -> 172482.66 | G4: ='04a_Projection_IS'!J97 -> 224462.83 | H4: ='04a_Projection_IS'!K97 -> 269077.71 | I4: ='04a_Projection_IS'!L97 -> 336929.53
A5: Adjustments to reconcile net income to net cash provided by operating activities:
A6: Stock-based compensation expense | B6: 2709 | C6: 3549 | D6: 4737 | E6: ='04b_Projection_BS'!E65 -> 5077.5902 | F6: ='04b_Projection_BS'!F65 -> 5607.3044 | G6: ='04b_Projection_BS'!G65 -> 6314.8074 | H6: ='04b_Projection_BS'!H65 -> 6868.9683 | I6: ='04b_Projection_BS'!I65 -> 8346.7343
A7: Depreciation and amortization | B7: 1544 | C7: 1508 | D7: 1864 | E7: ='11_DA'!B19 -> 3046.1976 | F7: ='11_DA'!C19 -> 4816.9738 | G7: ='11_DA'!D19 -> 6921.4049 | H7: ='11_DA'!E19 -> 9077.668 | I7: ='11_DA'!F19 -> 11117.025
A8: Deferred income taxes | B8: -2164 | C8: -2489 | D8: -4477 | E8: -4477 | F8: -4477 | G8: -4477 | H8: -4477 | I8: -4477
A9: (Gains) losses on non-marketable equity securities and publicly-held equity securities, net | B9: 45 | C9: -238 | D9: -1030 | E9: -1030 | F9: -1030 | G9: -1030 | H9: -1030 | I9: -1030
A10: Acquisition termination cost | B10: 1353 | C10: 0 | D10: 0 | E10: 0 | F10: 0 | G10: 0 | H10: 0 | I10: 0
A11: Other | B11: -7 | C11: -278 | D11: -502 | E11: -502 | F11: -502 | G11: -502 | H11: -502 | I11: -502
A12: Changes in operating assets and liabilities, net of acquisitions:
A13: Accounts receivable | B13: 822 | C13: -6172 | D13: -13063 | E13: =-('09_WorkingCapital'!G9-'09_WorkingCapital'!F9) -> -13749.144 | F13: =-('09_WorkingCapital'!H9-'09_WorkingCapital'!G9) -> -13730.661 | G13: =-('09_WorkingCapital'!I9-'09_WorkingCapital'!H9) -> -12056.548 | H13: =-('09_WorkingCapital'!J9-'09_WorkingCapital'!I9) -> -8573.3751 | I13: =-('09_WorkingCapital'!K9-'09_WorkingCapital'!J9) -> -13883.048
A14: Inventories | B14: -2554 | C14: -98 | D14: -4781 | E14: =-('09_WorkingCapital'!G10-'09_WorkingCapital'!F10) -> -4591.9365 | F14: =-('09_WorkingCapital'!H10-'09_WorkingCapital'!G10) -> -3166.2193 | G14: =-('09_WorkingCapital'!I10-'09_WorkingCapital'!H10) -> -1509.5824 | H14: =-('09_WorkingCapital'!J10-'09_WorkingCapital'!I10) -> 339.58819 | I14: =-('09_WorkingCapital'!K10-'09_WorkingCapital'!J10) -> -301.06601
A15: Prepaid expenses and other assets | B15: -1517 | C15: -1522 | D15: -395 | E15: =-('09_WorkingCapital'!G11-'09_WorkingCapital'!F11) -> -1303.263 | F15: =-('09_WorkingCapital'!H11-'09_WorkingCapital'!G11) -> -791.17411 | G15: =-('09_WorkingCapital'!I11-'09_WorkingCapital'!H11) -> -5.5472358 | H15: =-('09_WorkingCapital'!J11-'09_WorkingCapital'!I11) -> 204.08543 | I15: =-('09_WorkingCapital'!K11-'09_WorkingCapital'!J11) -> 85.020301
A16: Accounts payable | B16: -551 | C16: 1531 | D16: 3357 | E16: ='09_WorkingCapital'!G14-'09_WorkingCapital'!F14 -> 2968.5801 | F16: ='09_WorkingCapital'!H14-'09_WorkingCapital'!G14 -> 2369.6262 | G16: ='09_WorkingCapital'!I14-'09_WorkingCapital'!H14 -> 1423.9684 | H16: ='09_WorkingCapital'!J14-'09_WorkingCapital'!I14 -> 246.40701 | I16: ='09_WorkingCapital'!K14-'09_WorkingCapital'!J14 -> 748.04397
A17: Accrued and other current liabilities | B17: 1341 | C17: 2025 | D17: 4278 | E17: ='09_WorkingCapital'!G15-'09_WorkingCapital'!F15 -> 5989.6187 | F17: ='09_WorkingCapital'!H15-'09_WorkingCapital'!G15 -> 5376.4462 | G17: ='09_WorkingCapital'!I15-'09_WorkingCapital'!H15 -> 3842.4825 | H17: ='09_WorkingCapital'!J15-'09_WorkingCapital'!I15 -> 1833.4767 | I17: ='09_WorkingCapital'!K15-'09_WorkingCapital'!J15 -> 3320.0062
A18: Other long-term liabilities | B18: 252 | C18: 514 | D18: 1221 | E18: ='04b_Projection_BS'!G23-'04b_Projection_BS'!F23 -> 0 | F18: ='04b_Projection_BS'!H23-'04b_Projection_BS'!G23 -> 0 | G18: ='04b_Projection_BS'!I23-'04b_Projection_BS'!H23 -> 0 | H18: ='04b_Projection_BS'!J23-'04b_Projection_BS'!I23 -> 0 | I18: ='04b_Projection_BS'!K23-'04b_Projection_BS'!J23 -> 0
A19: Net cash provided by operating activities | B19: 5641 | C19: 28090 | D19: 64089 | E19: =SUM(E4:E18) -> 111256.81 | F19: =SUM(F4:F18) -> 166955.95 | G19: =SUM(G4:G18) -> 223384.82 | H19: =SUM(H4:H18) -> 273065.53 | I19: =SUM(I4:I18) -> 340353.24
A20: Cash flows from investing activities:
A21: Proceeds from maturities of marketable securities | B21: 19425 | C21: 9732 | D21: 11195 | E21: 0 | F21: 0 | G21: 0 | H21: 0 | I21: 0
A22: Proceeds from sales of marketable securities | B22: 1806 | C22: 50 | D22: 495 | E22: 0 | F22: 0 | G22: 0 | H22: 0 | I22: 0
